[2024-05-29T19:23:14.959+0000] {taskinstance.py:1083} INFO - Dependencies all met for <TaskInstance: conference_dag.load_conference manual__2024-05-29T19:22:45.082876+00:00 [queued]>
[2024-05-29T19:23:14.967+0000] {taskinstance.py:1083} INFO - Dependencies all met for <TaskInstance: conference_dag.load_conference manual__2024-05-29T19:22:45.082876+00:00 [queued]>
[2024-05-29T19:23:14.967+0000] {taskinstance.py:1279} INFO - 
--------------------------------------------------------------------------------
[2024-05-29T19:23:14.968+0000] {taskinstance.py:1280} INFO - Starting attempt 1 of 1
[2024-05-29T19:23:14.969+0000] {taskinstance.py:1281} INFO - 
--------------------------------------------------------------------------------
[2024-05-29T19:23:14.979+0000] {taskinstance.py:1300} INFO - Executing <Task(BashOperator): load_conference> on 2024-05-29 19:22:45.082876+00:00
[2024-05-29T19:23:14.983+0000] {standard_task_runner.py:55} INFO - Started process 44135 to run task
[2024-05-29T19:23:14.985+0000] {standard_task_runner.py:82} INFO - Running: ['***', 'tasks', 'run', 'conference_dag', 'load_conference', 'manual__2024-05-29T19:22:45.082876+00:00', '--job-id', '361', '--raw', '--subdir', 'DAGS_FOLDER/conference_dag.py', '--cfg-path', '/tmp/tmp_24sd5pr']
[2024-05-29T19:23:14.986+0000] {standard_task_runner.py:83} INFO - Job 361: Subtask load_conference
[2024-05-29T19:23:15.031+0000] {task_command.py:388} INFO - Running <TaskInstance: conference_dag.load_conference manual__2024-05-29T19:22:45.082876+00:00 [running]> on host 731e27f62632
[2024-05-29T19:23:15.078+0000] {taskinstance.py:1509} INFO - Exporting the following env vars:
AIRFLOW_CTX_DAG_OWNER=***
AIRFLOW_CTX_DAG_ID=conference_dag
AIRFLOW_CTX_TASK_ID=load_conference
AIRFLOW_CTX_EXECUTION_DATE=2024-05-29T19:22:45.082876+00:00
AIRFLOW_CTX_TRY_NUMBER=1
AIRFLOW_CTX_DAG_RUN_ID=manual__2024-05-29T19:22:45.082876+00:00
[2024-05-29T19:23:15.080+0000] {subprocess.py:63} INFO - Tmp dir root location: 
 /tmp
[2024-05-29T19:23:15.081+0000] {subprocess.py:75} INFO - Running command: ['/bin/bash', '-c', 'set -e; python /opt/***/mysql_utils/load_conference.py']
[2024-05-29T19:23:15.088+0000] {subprocess.py:86} INFO - Output:
[2024-05-29T19:23:15.301+0000] {subprocess.py:93} INFO - Traceback (most recent call last):
[2024-05-29T19:23:15.301+0000] {subprocess.py:93} INFO -   File "/opt/***/mysql_utils/load_conference.py", line 30, in <module>
[2024-05-29T19:23:15.302+0000] {subprocess.py:93} INFO -     (row['name'], row['link'], deadline, row['subformat'], row['field_id'], row['presenter_id'], row['location_id'], from_date, to_date, report_date)
[2024-05-29T19:23:15.302+0000] {subprocess.py:93} INFO -   File "/home/***/.local/lib/python3.7/site-packages/pymysql/cursors.py", line 153, in execute
[2024-05-29T19:23:15.303+0000] {subprocess.py:93} INFO -     result = self._query(query)
[2024-05-29T19:23:15.303+0000] {subprocess.py:93} INFO -   File "/home/***/.local/lib/python3.7/site-packages/pymysql/cursors.py", line 322, in _query
[2024-05-29T19:23:15.304+0000] {subprocess.py:93} INFO -     conn.query(q)
[2024-05-29T19:23:15.304+0000] {subprocess.py:93} INFO -   File "/home/***/.local/lib/python3.7/site-packages/pymysql/connections.py", line 563, in query
[2024-05-29T19:23:15.304+0000] {subprocess.py:93} INFO -     self._affected_rows = self._read_query_result(unbuffered=unbuffered)
[2024-05-29T19:23:15.305+0000] {subprocess.py:93} INFO -   File "/home/***/.local/lib/python3.7/site-packages/pymysql/connections.py", line 825, in _read_query_result
[2024-05-29T19:23:15.305+0000] {subprocess.py:93} INFO -     result.read()
[2024-05-29T19:23:15.305+0000] {subprocess.py:93} INFO -   File "/home/***/.local/lib/python3.7/site-packages/pymysql/connections.py", line 1199, in read
[2024-05-29T19:23:15.306+0000] {subprocess.py:93} INFO -     first_packet = self.connection._read_packet()
[2024-05-29T19:23:15.306+0000] {subprocess.py:93} INFO -   File "/home/***/.local/lib/python3.7/site-packages/pymysql/connections.py", line 775, in _read_packet
[2024-05-29T19:23:15.306+0000] {subprocess.py:93} INFO -     packet.raise_for_error()
[2024-05-29T19:23:15.307+0000] {subprocess.py:93} INFO -   File "/home/***/.local/lib/python3.7/site-packages/pymysql/protocol.py", line 219, in raise_for_error
[2024-05-29T19:23:15.307+0000] {subprocess.py:93} INFO -     err.raise_mysql_exception(self._data)
[2024-05-29T19:23:15.308+0000] {subprocess.py:93} INFO -   File "/home/***/.local/lib/python3.7/site-packages/pymysql/err.py", line 150, in raise_mysql_exception
[2024-05-29T19:23:15.308+0000] {subprocess.py:93} INFO -     raise errorclass(errno, errval)
[2024-05-29T19:23:15.309+0000] {subprocess.py:93} INFO - pymysql.err.OperationalError: (1364, "Field 'id' doesn't have a default value")
[2024-05-29T19:23:15.309+0000] {subprocess.py:97} INFO - Command exited with return code 1
[2024-05-29T19:23:15.317+0000] {taskinstance.py:1768} ERROR - Task failed with exception
Traceback (most recent call last):
  File "/home/airflow/.local/lib/python3.7/site-packages/airflow/operators/bash.py", line 197, in execute
    f"Bash command failed. The command returned a non-zero exit code {result.exit_code}."
airflow.exceptions.AirflowException: Bash command failed. The command returned a non-zero exit code 1.
[2024-05-29T19:23:15.320+0000] {taskinstance.py:1323} INFO - Marking task as FAILED. dag_id=conference_dag, task_id=load_conference, execution_date=20240529T192245, start_date=20240529T192314, end_date=20240529T192315
[2024-05-29T19:23:15.328+0000] {standard_task_runner.py:105} ERROR - Failed to execute job 361 for task load_conference (Bash command failed. The command returned a non-zero exit code 1.; 44135)
[2024-05-29T19:23:15.360+0000] {local_task_job.py:208} INFO - Task exited with return code 1
[2024-05-29T19:23:15.377+0000] {taskinstance.py:2578} INFO - 0 downstream tasks scheduled from follow-on schedule check
