[2024-05-29T18:10:45.632+0000] {taskinstance.py:1083} INFO - Dependencies all met for <TaskInstance: conference_dag.load_data manual__2024-05-29T18:07:45.441451+00:00 [queued]>
[2024-05-29T18:10:45.642+0000] {taskinstance.py:1083} INFO - Dependencies all met for <TaskInstance: conference_dag.load_data manual__2024-05-29T18:07:45.441451+00:00 [queued]>
[2024-05-29T18:10:45.643+0000] {taskinstance.py:1279} INFO - 
--------------------------------------------------------------------------------
[2024-05-29T18:10:45.644+0000] {taskinstance.py:1280} INFO - Starting attempt 2 of 2
[2024-05-29T18:10:45.644+0000] {taskinstance.py:1281} INFO - 
--------------------------------------------------------------------------------
[2024-05-29T18:10:45.660+0000] {taskinstance.py:1300} INFO - Executing <Task(BashOperator): load_data> on 2024-05-29 18:07:45.441451+00:00
[2024-05-29T18:10:45.664+0000] {standard_task_runner.py:55} INFO - Started process 34890 to run task
[2024-05-29T18:10:45.666+0000] {standard_task_runner.py:82} INFO - Running: ['***', 'tasks', 'run', 'conference_dag', 'load_data', 'manual__2024-05-29T18:07:45.441451+00:00', '--job-id', '302', '--raw', '--subdir', 'DAGS_FOLDER/conference_dag.py', '--cfg-path', '/tmp/tmpqzixlwgj']
[2024-05-29T18:10:45.667+0000] {standard_task_runner.py:83} INFO - Job 302: Subtask load_data
[2024-05-29T18:10:45.730+0000] {task_command.py:388} INFO - Running <TaskInstance: conference_dag.load_data manual__2024-05-29T18:07:45.441451+00:00 [running]> on host 731e27f62632
[2024-05-29T18:10:45.804+0000] {taskinstance.py:1509} INFO - Exporting the following env vars:
AIRFLOW_CTX_DAG_OWNER=***
AIRFLOW_CTX_DAG_ID=conference_dag
AIRFLOW_CTX_TASK_ID=load_data
AIRFLOW_CTX_EXECUTION_DATE=2024-05-29T18:07:45.441451+00:00
AIRFLOW_CTX_TRY_NUMBER=2
AIRFLOW_CTX_DAG_RUN_ID=manual__2024-05-29T18:07:45.441451+00:00
[2024-05-29T18:10:45.806+0000] {subprocess.py:63} INFO - Tmp dir root location: 
 /tmp
[2024-05-29T18:10:45.808+0000] {subprocess.py:75} INFO - Running command: ['/bin/bash', '-c', 'set -e; python /opt/***/mysql_utils/load_to_db.py']
[2024-05-29T18:10:45.817+0000] {subprocess.py:86} INFO - Output:
[2024-05-29T18:10:46.044+0000] {subprocess.py:93} INFO - Traceback (most recent call last):
[2024-05-29T18:10:46.045+0000] {subprocess.py:93} INFO -   File "/opt/***/mysql_utils/load_to_db.py", line 17, in <module>
[2024-05-29T18:10:46.045+0000] {subprocess.py:93} INFO -     cur.execute('INSERT INTO locations(id, city, country) VALUES(%s, %s, %s)', (row['id'], row['City'], row['Country']))
[2024-05-29T18:10:46.046+0000] {subprocess.py:93} INFO -   File "/home/***/.local/lib/python3.7/site-packages/pymysql/cursors.py", line 153, in execute
[2024-05-29T18:10:46.046+0000] {subprocess.py:93} INFO -     result = self._query(query)
[2024-05-29T18:10:46.046+0000] {subprocess.py:93} INFO -   File "/home/***/.local/lib/python3.7/site-packages/pymysql/cursors.py", line 322, in _query
[2024-05-29T18:10:46.047+0000] {subprocess.py:93} INFO -     conn.query(q)
[2024-05-29T18:10:46.047+0000] {subprocess.py:93} INFO -   File "/home/***/.local/lib/python3.7/site-packages/pymysql/connections.py", line 563, in query
[2024-05-29T18:10:46.048+0000] {subprocess.py:93} INFO -     self._affected_rows = self._read_query_result(unbuffered=unbuffered)
[2024-05-29T18:10:46.048+0000] {subprocess.py:93} INFO -   File "/home/***/.local/lib/python3.7/site-packages/pymysql/connections.py", line 825, in _read_query_result
[2024-05-29T18:10:46.048+0000] {subprocess.py:93} INFO -     result.read()
[2024-05-29T18:10:46.049+0000] {subprocess.py:93} INFO -   File "/home/***/.local/lib/python3.7/site-packages/pymysql/connections.py", line 1199, in read
[2024-05-29T18:10:46.049+0000] {subprocess.py:93} INFO -     first_packet = self.connection._read_packet()
[2024-05-29T18:10:46.050+0000] {subprocess.py:93} INFO -   File "/home/***/.local/lib/python3.7/site-packages/pymysql/connections.py", line 775, in _read_packet
[2024-05-29T18:10:46.050+0000] {subprocess.py:93} INFO -     packet.raise_for_error()
[2024-05-29T18:10:46.051+0000] {subprocess.py:93} INFO -   File "/home/***/.local/lib/python3.7/site-packages/pymysql/protocol.py", line 219, in raise_for_error
[2024-05-29T18:10:46.051+0000] {subprocess.py:93} INFO -     err.raise_mysql_exception(self._data)
[2024-05-29T18:10:46.052+0000] {subprocess.py:93} INFO -   File "/home/***/.local/lib/python3.7/site-packages/pymysql/err.py", line 150, in raise_mysql_exception
[2024-05-29T18:10:46.052+0000] {subprocess.py:93} INFO -     raise errorclass(errno, errval)
[2024-05-29T18:10:46.053+0000] {subprocess.py:93} INFO - pymysql.err.IntegrityError: (1062, "Duplicate entry '1' for key 'locations.PRIMARY'")
[2024-05-29T18:10:46.053+0000] {subprocess.py:97} INFO - Command exited with return code 1
[2024-05-29T18:10:46.062+0000] {taskinstance.py:1768} ERROR - Task failed with exception
Traceback (most recent call last):
  File "/home/airflow/.local/lib/python3.7/site-packages/airflow/operators/bash.py", line 197, in execute
    f"Bash command failed. The command returned a non-zero exit code {result.exit_code}."
airflow.exceptions.AirflowException: Bash command failed. The command returned a non-zero exit code 1.
[2024-05-29T18:10:46.065+0000] {taskinstance.py:1323} INFO - Marking task as FAILED. dag_id=conference_dag, task_id=load_data, execution_date=20240529T180745, start_date=20240529T181045, end_date=20240529T181046
[2024-05-29T18:10:46.076+0000] {standard_task_runner.py:105} ERROR - Failed to execute job 302 for task load_data (Bash command failed. The command returned a non-zero exit code 1.; 34890)
[2024-05-29T18:10:46.120+0000] {local_task_job.py:208} INFO - Task exited with return code 1
[2024-05-29T18:10:46.143+0000] {taskinstance.py:2578} INFO - 0 downstream tasks scheduled from follow-on schedule check
