[2024-05-29T18:10:57.496+0000] {taskinstance.py:1083} INFO - Dependencies all met for <TaskInstance: conference_dag.transform_field manual__2024-05-29T18:10:48.296103+00:00 [queued]>
[2024-05-29T18:10:57.504+0000] {taskinstance.py:1083} INFO - Dependencies all met for <TaskInstance: conference_dag.transform_field manual__2024-05-29T18:10:48.296103+00:00 [queued]>
[2024-05-29T18:10:57.505+0000] {taskinstance.py:1279} INFO - 
--------------------------------------------------------------------------------
[2024-05-29T18:10:57.505+0000] {taskinstance.py:1280} INFO - Starting attempt 1 of 1
[2024-05-29T18:10:57.506+0000] {taskinstance.py:1281} INFO - 
--------------------------------------------------------------------------------
[2024-05-29T18:10:57.516+0000] {taskinstance.py:1300} INFO - Executing <Task(BashOperator): transform_field> on 2024-05-29 18:10:48.296103+00:00
[2024-05-29T18:10:57.521+0000] {standard_task_runner.py:55} INFO - Started process 34931 to run task
[2024-05-29T18:10:57.524+0000] {standard_task_runner.py:82} INFO - Running: ['***', 'tasks', 'run', 'conference_dag', 'transform_field', 'manual__2024-05-29T18:10:48.296103+00:00', '--job-id', '304', '--raw', '--subdir', 'DAGS_FOLDER/conference_dag.py', '--cfg-path', '/tmp/tmp1okexh5w']
[2024-05-29T18:10:57.525+0000] {standard_task_runner.py:83} INFO - Job 304: Subtask transform_field
[2024-05-29T18:10:57.578+0000] {task_command.py:388} INFO - Running <TaskInstance: conference_dag.transform_field manual__2024-05-29T18:10:48.296103+00:00 [running]> on host 731e27f62632
[2024-05-29T18:10:57.635+0000] {taskinstance.py:1509} INFO - Exporting the following env vars:
AIRFLOW_CTX_DAG_OWNER=***
AIRFLOW_CTX_DAG_ID=conference_dag
AIRFLOW_CTX_TASK_ID=transform_field
AIRFLOW_CTX_EXECUTION_DATE=2024-05-29T18:10:48.296103+00:00
AIRFLOW_CTX_TRY_NUMBER=1
AIRFLOW_CTX_DAG_RUN_ID=manual__2024-05-29T18:10:48.296103+00:00
[2024-05-29T18:10:57.636+0000] {subprocess.py:63} INFO - Tmp dir root location: 
 /tmp
[2024-05-29T18:10:57.637+0000] {subprocess.py:75} INFO - Running command: ['/bin/bash', '-c', 'set -e; python /opt/***/data_transform/transform_field.py']
[2024-05-29T18:10:57.645+0000] {subprocess.py:86} INFO - Output:
[2024-05-29T18:10:57.775+0000] {subprocess.py:93} INFO - Traceback (most recent call last):
[2024-05-29T18:10:57.775+0000] {subprocess.py:93} INFO -   File "/opt/***/data_transform/transform_field.py", line 19, in <module>
[2024-05-29T18:10:57.776+0000] {subprocess.py:93} INFO -     data = json.load(file)
[2024-05-29T18:10:57.777+0000] {subprocess.py:93} INFO -   File "/usr/local/lib/python3.7/json/__init__.py", line 296, in load
[2024-05-29T18:10:57.778+0000] {subprocess.py:93} INFO -     parse_constant=parse_constant, object_pairs_hook=object_pairs_hook, **kw)
[2024-05-29T18:10:57.779+0000] {subprocess.py:93} INFO -   File "/usr/local/lib/python3.7/json/__init__.py", line 348, in loads
[2024-05-29T18:10:57.779+0000] {subprocess.py:93} INFO -     return _default_decoder.decode(s)
[2024-05-29T18:10:57.780+0000] {subprocess.py:93} INFO -   File "/usr/local/lib/python3.7/json/decoder.py", line 340, in decode
[2024-05-29T18:10:57.781+0000] {subprocess.py:93} INFO -     raise JSONDecodeError("Extra data", s, end)
[2024-05-29T18:10:57.781+0000] {subprocess.py:93} INFO - json.decoder.JSONDecodeError: Extra data: line 46 column 2 (char 10922)
[2024-05-29T18:10:57.782+0000] {subprocess.py:97} INFO - Command exited with return code 1
[2024-05-29T18:10:57.791+0000] {taskinstance.py:1768} ERROR - Task failed with exception
Traceback (most recent call last):
  File "/home/airflow/.local/lib/python3.7/site-packages/airflow/operators/bash.py", line 197, in execute
    f"Bash command failed. The command returned a non-zero exit code {result.exit_code}."
airflow.exceptions.AirflowException: Bash command failed. The command returned a non-zero exit code 1.
[2024-05-29T18:10:57.794+0000] {taskinstance.py:1323} INFO - Marking task as FAILED. dag_id=conference_dag, task_id=transform_field, execution_date=20240529T181048, start_date=20240529T181057, end_date=20240529T181057
[2024-05-29T18:10:57.805+0000] {standard_task_runner.py:105} ERROR - Failed to execute job 304 for task transform_field (Bash command failed. The command returned a non-zero exit code 1.; 34931)
[2024-05-29T18:10:57.817+0000] {local_task_job.py:208} INFO - Task exited with return code 1
[2024-05-29T18:10:57.835+0000] {taskinstance.py:2578} INFO - 0 downstream tasks scheduled from follow-on schedule check
