[2024-05-29T18:10:45.626+0000] {taskinstance.py:1083} INFO - Dependencies all met for <TaskInstance: conference_dag.transform_field manual__2024-05-29T18:10:36.226350+00:00 [queued]>
[2024-05-29T18:10:45.635+0000] {taskinstance.py:1083} INFO - Dependencies all met for <TaskInstance: conference_dag.transform_field manual__2024-05-29T18:10:36.226350+00:00 [queued]>
[2024-05-29T18:10:45.636+0000] {taskinstance.py:1279} INFO - 
--------------------------------------------------------------------------------
[2024-05-29T18:10:45.636+0000] {taskinstance.py:1280} INFO - Starting attempt 1 of 1
[2024-05-29T18:10:45.637+0000] {taskinstance.py:1281} INFO - 
--------------------------------------------------------------------------------
[2024-05-29T18:10:45.651+0000] {taskinstance.py:1300} INFO - Executing <Task(BashOperator): transform_field> on 2024-05-29 18:10:36.226350+00:00
[2024-05-29T18:10:45.656+0000] {standard_task_runner.py:55} INFO - Started process 34889 to run task
[2024-05-29T18:10:45.659+0000] {standard_task_runner.py:82} INFO - Running: ['***', 'tasks', 'run', 'conference_dag', 'transform_field', 'manual__2024-05-29T18:10:36.226350+00:00', '--job-id', '301', '--raw', '--subdir', 'DAGS_FOLDER/conference_dag.py', '--cfg-path', '/tmp/tmpl2rv3zvy']
[2024-05-29T18:10:45.660+0000] {standard_task_runner.py:83} INFO - Job 301: Subtask transform_field
[2024-05-29T18:10:45.722+0000] {task_command.py:388} INFO - Running <TaskInstance: conference_dag.transform_field manual__2024-05-29T18:10:36.226350+00:00 [running]> on host 731e27f62632
[2024-05-29T18:10:45.796+0000] {taskinstance.py:1509} INFO - Exporting the following env vars:
AIRFLOW_CTX_DAG_OWNER=***
AIRFLOW_CTX_DAG_ID=conference_dag
AIRFLOW_CTX_TASK_ID=transform_field
AIRFLOW_CTX_EXECUTION_DATE=2024-05-29T18:10:36.226350+00:00
AIRFLOW_CTX_TRY_NUMBER=1
AIRFLOW_CTX_DAG_RUN_ID=manual__2024-05-29T18:10:36.226350+00:00
[2024-05-29T18:10:45.797+0000] {subprocess.py:63} INFO - Tmp dir root location: 
 /tmp
[2024-05-29T18:10:45.799+0000] {subprocess.py:75} INFO - Running command: ['/bin/bash', '-c', 'set -e; python /opt/***/data_transform/transform_field.py']
[2024-05-29T18:10:45.810+0000] {subprocess.py:86} INFO - Output:
[2024-05-29T18:10:45.945+0000] {subprocess.py:93} INFO - Traceback (most recent call last):
[2024-05-29T18:10:45.946+0000] {subprocess.py:93} INFO -   File "/opt/***/data_transform/transform_field.py", line 19, in <module>
[2024-05-29T18:10:45.947+0000] {subprocess.py:93} INFO -     data = json.load(file)
[2024-05-29T18:10:45.947+0000] {subprocess.py:93} INFO -   File "/usr/local/lib/python3.7/json/__init__.py", line 296, in load
[2024-05-29T18:10:45.948+0000] {subprocess.py:93} INFO -     parse_constant=parse_constant, object_pairs_hook=object_pairs_hook, **kw)
[2024-05-29T18:10:45.948+0000] {subprocess.py:93} INFO -   File "/usr/local/lib/python3.7/json/__init__.py", line 348, in loads
[2024-05-29T18:10:45.949+0000] {subprocess.py:93} INFO -     return _default_decoder.decode(s)
[2024-05-29T18:10:45.949+0000] {subprocess.py:93} INFO -   File "/usr/local/lib/python3.7/json/decoder.py", line 340, in decode
[2024-05-29T18:10:45.950+0000] {subprocess.py:93} INFO -     raise JSONDecodeError("Extra data", s, end)
[2024-05-29T18:10:45.950+0000] {subprocess.py:93} INFO - json.decoder.JSONDecodeError: Extra data: line 46 column 2 (char 10922)
[2024-05-29T18:10:45.951+0000] {subprocess.py:97} INFO - Command exited with return code 1
[2024-05-29T18:10:45.962+0000] {taskinstance.py:1768} ERROR - Task failed with exception
Traceback (most recent call last):
  File "/home/airflow/.local/lib/python3.7/site-packages/airflow/operators/bash.py", line 197, in execute
    f"Bash command failed. The command returned a non-zero exit code {result.exit_code}."
airflow.exceptions.AirflowException: Bash command failed. The command returned a non-zero exit code 1.
[2024-05-29T18:10:45.965+0000] {taskinstance.py:1323} INFO - Marking task as FAILED. dag_id=conference_dag, task_id=transform_field, execution_date=20240529T181036, start_date=20240529T181045, end_date=20240529T181045
[2024-05-29T18:10:45.978+0000] {standard_task_runner.py:105} ERROR - Failed to execute job 301 for task transform_field (Bash command failed. The command returned a non-zero exit code 1.; 34889)
[2024-05-29T18:10:45.993+0000] {local_task_job.py:208} INFO - Task exited with return code 1
[2024-05-29T18:10:46.014+0000] {taskinstance.py:2578} INFO - 0 downstream tasks scheduled from follow-on schedule check
