[2024-05-30T03:10:11.530+0000] {taskinstance.py:1083} INFO - Dependencies all met for <TaskInstance: conference_dag.clean_data manual__2024-05-30T03:10:09.518267+00:00 [queued]>
[2024-05-30T03:10:11.538+0000] {taskinstance.py:1083} INFO - Dependencies all met for <TaskInstance: conference_dag.clean_data manual__2024-05-30T03:10:09.518267+00:00 [queued]>
[2024-05-30T03:10:11.539+0000] {taskinstance.py:1279} INFO - 
--------------------------------------------------------------------------------
[2024-05-30T03:10:11.540+0000] {taskinstance.py:1280} INFO - Starting attempt 1 of 1
[2024-05-30T03:10:11.540+0000] {taskinstance.py:1281} INFO - 
--------------------------------------------------------------------------------
[2024-05-30T03:10:11.552+0000] {taskinstance.py:1300} INFO - Executing <Task(BashOperator): clean_data> on 2024-05-30 03:10:09.518267+00:00
[2024-05-30T03:10:11.556+0000] {standard_task_runner.py:55} INFO - Started process 3344 to run task
[2024-05-30T03:10:11.558+0000] {standard_task_runner.py:82} INFO - Running: ['***', 'tasks', 'run', 'conference_dag', 'clean_data', 'manual__2024-05-30T03:10:09.518267+00:00', '--job-id', '382', '--raw', '--subdir', 'DAGS_FOLDER/conference_dag.py', '--cfg-path', '/tmp/tmpvcww5f65']
[2024-05-30T03:10:11.559+0000] {standard_task_runner.py:83} INFO - Job 382: Subtask clean_data
[2024-05-30T03:10:11.611+0000] {task_command.py:388} INFO - Running <TaskInstance: conference_dag.clean_data manual__2024-05-30T03:10:09.518267+00:00 [running]> on host 731e27f62632
[2024-05-30T03:10:11.674+0000] {taskinstance.py:1509} INFO - Exporting the following env vars:
AIRFLOW_CTX_DAG_OWNER=***
AIRFLOW_CTX_DAG_ID=conference_dag
AIRFLOW_CTX_TASK_ID=clean_data
AIRFLOW_CTX_EXECUTION_DATE=2024-05-30T03:10:09.518267+00:00
AIRFLOW_CTX_TRY_NUMBER=1
AIRFLOW_CTX_DAG_RUN_ID=manual__2024-05-30T03:10:09.518267+00:00
[2024-05-30T03:10:11.676+0000] {subprocess.py:63} INFO - Tmp dir root location: 
 /tmp
[2024-05-30T03:10:11.678+0000] {subprocess.py:75} INFO - Running command: ['/bin/bash', '-c', 'set -e; python /opt/***/crawling/clean_all.py']
[2024-05-30T03:10:11.686+0000] {subprocess.py:86} INFO - Output:
[2024-05-30T03:10:11.742+0000] {subprocess.py:93} INFO - python: can't open file '/opt/***/crawling/clean_all.py': [Errno 2] No such file or directory
[2024-05-30T03:10:11.744+0000] {subprocess.py:97} INFO - Command exited with return code 2
[2024-05-30T03:10:11.753+0000] {taskinstance.py:1768} ERROR - Task failed with exception
Traceback (most recent call last):
  File "/home/airflow/.local/lib/python3.7/site-packages/airflow/operators/bash.py", line 197, in execute
    f"Bash command failed. The command returned a non-zero exit code {result.exit_code}."
airflow.exceptions.AirflowException: Bash command failed. The command returned a non-zero exit code 2.
[2024-05-30T03:10:11.756+0000] {taskinstance.py:1323} INFO - Marking task as FAILED. dag_id=conference_dag, task_id=clean_data, execution_date=20240530T031009, start_date=20240530T031011, end_date=20240530T031011
[2024-05-30T03:10:11.767+0000] {standard_task_runner.py:105} ERROR - Failed to execute job 382 for task clean_data (Bash command failed. The command returned a non-zero exit code 2.; 3344)
[2024-05-30T03:10:11.813+0000] {local_task_job.py:208} INFO - Task exited with return code 1
[2024-05-30T03:10:11.847+0000] {taskinstance.py:2578} INFO - 0 downstream tasks scheduled from follow-on schedule check
