[2024-05-31T10:53:11.878+0000] {taskinstance.py:1083} INFO - Dependencies all met for <TaskInstance: conference_dag.clean_data manual__2024-05-31T10:53:09.772742+00:00 [queued]>
[2024-05-31T10:53:11.885+0000] {taskinstance.py:1083} INFO - Dependencies all met for <TaskInstance: conference_dag.clean_data manual__2024-05-31T10:53:09.772742+00:00 [queued]>
[2024-05-31T10:53:11.886+0000] {taskinstance.py:1279} INFO - 
--------------------------------------------------------------------------------
[2024-05-31T10:53:11.886+0000] {taskinstance.py:1280} INFO - Starting attempt 1 of 1
[2024-05-31T10:53:11.886+0000] {taskinstance.py:1281} INFO - 
--------------------------------------------------------------------------------
[2024-05-31T10:53:11.898+0000] {taskinstance.py:1300} INFO - Executing <Task(BashOperator): clean_data> on 2024-05-31 10:53:09.772742+00:00
[2024-05-31T10:53:11.902+0000] {standard_task_runner.py:55} INFO - Started process 645 to run task
[2024-05-31T10:53:11.904+0000] {standard_task_runner.py:82} INFO - Running: ['***', 'tasks', 'run', 'conference_dag', 'clean_data', 'manual__2024-05-31T10:53:09.772742+00:00', '--job-id', '5', '--raw', '--subdir', 'DAGS_FOLDER/conference_dag.py', '--cfg-path', '/tmp/tmpaqpyo6ok']
[2024-05-31T10:53:11.905+0000] {standard_task_runner.py:83} INFO - Job 5: Subtask clean_data
[2024-05-31T10:53:11.955+0000] {task_command.py:388} INFO - Running <TaskInstance: conference_dag.clean_data manual__2024-05-31T10:53:09.772742+00:00 [running]> on host 312e62f5d623
[2024-05-31T10:53:12.011+0000] {taskinstance.py:1509} INFO - Exporting the following env vars:
AIRFLOW_CTX_DAG_OWNER=***
AIRFLOW_CTX_DAG_ID=conference_dag
AIRFLOW_CTX_TASK_ID=clean_data
AIRFLOW_CTX_EXECUTION_DATE=2024-05-31T10:53:09.772742+00:00
AIRFLOW_CTX_TRY_NUMBER=1
AIRFLOW_CTX_DAG_RUN_ID=manual__2024-05-31T10:53:09.772742+00:00
[2024-05-31T10:53:12.012+0000] {subprocess.py:63} INFO - Tmp dir root location: 
 /tmp
[2024-05-31T10:53:12.013+0000] {subprocess.py:75} INFO - Running command: ['/bin/bash', '-c', 'set -e; python /opt/***/dags/clean_all.py']
[2024-05-31T10:53:12.020+0000] {subprocess.py:86} INFO - Output:
[2024-05-31T10:53:12.198+0000] {subprocess.py:93} INFO - Traceback (most recent call last):
[2024-05-31T10:53:12.199+0000] {subprocess.py:93} INFO -   File "/opt/***/dags/clean_all.py", line 16, in <module>
[2024-05-31T10:53:12.199+0000] {subprocess.py:93} INFO -     cur.execute('DELETE FROM ***.conferences;')
[2024-05-31T10:53:12.199+0000] {subprocess.py:93} INFO -   File "/home/***/.local/lib/python3.7/site-packages/pymysql/cursors.py", line 153, in execute
[2024-05-31T10:53:12.199+0000] {subprocess.py:93} INFO -     result = self._query(query)
[2024-05-31T10:53:12.199+0000] {subprocess.py:93} INFO -   File "/home/***/.local/lib/python3.7/site-packages/pymysql/cursors.py", line 322, in _query
[2024-05-31T10:53:12.199+0000] {subprocess.py:93} INFO -     conn.query(q)
[2024-05-31T10:53:12.200+0000] {subprocess.py:93} INFO -   File "/home/***/.local/lib/python3.7/site-packages/pymysql/connections.py", line 563, in query
[2024-05-31T10:53:12.200+0000] {subprocess.py:93} INFO -     self._affected_rows = self._read_query_result(unbuffered=unbuffered)
[2024-05-31T10:53:12.200+0000] {subprocess.py:93} INFO -   File "/home/***/.local/lib/python3.7/site-packages/pymysql/connections.py", line 825, in _read_query_result
[2024-05-31T10:53:12.200+0000] {subprocess.py:93} INFO -     result.read()
[2024-05-31T10:53:12.200+0000] {subprocess.py:93} INFO -   File "/home/***/.local/lib/python3.7/site-packages/pymysql/connections.py", line 1199, in read
[2024-05-31T10:53:12.200+0000] {subprocess.py:93} INFO -     first_packet = self.connection._read_packet()
[2024-05-31T10:53:12.200+0000] {subprocess.py:93} INFO -   File "/home/***/.local/lib/python3.7/site-packages/pymysql/connections.py", line 775, in _read_packet
[2024-05-31T10:53:12.201+0000] {subprocess.py:93} INFO -     packet.raise_for_error()
[2024-05-31T10:53:12.201+0000] {subprocess.py:93} INFO -   File "/home/***/.local/lib/python3.7/site-packages/pymysql/protocol.py", line 219, in raise_for_error
[2024-05-31T10:53:12.201+0000] {subprocess.py:93} INFO -     err.raise_mysql_exception(self._data)
[2024-05-31T10:53:12.201+0000] {subprocess.py:93} INFO -   File "/home/***/.local/lib/python3.7/site-packages/pymysql/err.py", line 150, in raise_mysql_exception
[2024-05-31T10:53:12.201+0000] {subprocess.py:93} INFO -     raise errorclass(errno, errval)
[2024-05-31T10:53:12.201+0000] {subprocess.py:93} INFO - pymysql.err.ProgrammingError: (1146, "Table '***.conferences' doesn't exist")
[2024-05-31T10:53:12.204+0000] {subprocess.py:97} INFO - Command exited with return code 1
[2024-05-31T10:53:12.211+0000] {taskinstance.py:1768} ERROR - Task failed with exception
Traceback (most recent call last):
  File "/home/airflow/.local/lib/python3.7/site-packages/airflow/operators/bash.py", line 197, in execute
    f"Bash command failed. The command returned a non-zero exit code {result.exit_code}."
airflow.exceptions.AirflowException: Bash command failed. The command returned a non-zero exit code 1.
[2024-05-31T10:53:12.214+0000] {taskinstance.py:1323} INFO - Marking task as FAILED. dag_id=conference_dag, task_id=clean_data, execution_date=20240531T105309, start_date=20240531T105311, end_date=20240531T105312
[2024-05-31T10:53:12.224+0000] {standard_task_runner.py:105} ERROR - Failed to execute job 5 for task clean_data (Bash command failed. The command returned a non-zero exit code 1.; 645)
[2024-05-31T10:53:12.237+0000] {local_task_job.py:208} INFO - Task exited with return code 1
[2024-05-31T10:53:12.259+0000] {taskinstance.py:2578} INFO - 0 downstream tasks scheduled from follow-on schedule check
