[2024-05-27T03:02:20.955+0000] {taskinstance.py:1083} INFO - Dependencies all met for <TaskInstance: conference_dag.set_up_database manual__2024-05-27T03:02:20.102771+00:00 [queued]>
[2024-05-27T03:02:20.963+0000] {taskinstance.py:1083} INFO - Dependencies all met for <TaskInstance: conference_dag.set_up_database manual__2024-05-27T03:02:20.102771+00:00 [queued]>
[2024-05-27T03:02:20.964+0000] {taskinstance.py:1279} INFO - 
--------------------------------------------------------------------------------
[2024-05-27T03:02:20.964+0000] {taskinstance.py:1280} INFO - Starting attempt 1 of 1
[2024-05-27T03:02:20.965+0000] {taskinstance.py:1281} INFO - 
--------------------------------------------------------------------------------
[2024-05-27T03:02:20.980+0000] {taskinstance.py:1300} INFO - Executing <Task(MySqlOperator): set_up_database> on 2024-05-27 03:02:20.102771+00:00
[2024-05-27T03:02:20.985+0000] {standard_task_runner.py:55} INFO - Started process 2750 to run task
[2024-05-27T03:02:20.988+0000] {standard_task_runner.py:82} INFO - Running: ['***', 'tasks', 'run', 'conference_dag', 'set_up_database', 'manual__2024-05-27T03:02:20.102771+00:00', '--job-id', '85', '--raw', '--subdir', 'DAGS_FOLDER/conference_dag.py', '--cfg-path', '/tmp/tmpssqtuhyh']
[2024-05-27T03:02:20.988+0000] {standard_task_runner.py:83} INFO - Job 85: Subtask set_up_database
[2024-05-27T03:02:21.045+0000] {task_command.py:388} INFO - Running <TaskInstance: conference_dag.set_up_database manual__2024-05-27T03:02:20.102771+00:00 [running]> on host 731e27f62632
[2024-05-27T03:02:21.075+0000] {abstractoperator.py:613} ERROR - Exception rendering Jinja template for task 'set_up_database', field 'sql'. Template: '/opt/***/mysql_utils/set_up_database.sql'
Traceback (most recent call last):
  File "/home/airflow/.local/lib/python3.7/site-packages/airflow/models/abstractoperator.py", line 606, in _do_render_template_fields
    seen_oids,
  File "/home/airflow/.local/lib/python3.7/site-packages/airflow/models/abstractoperator.py", line 657, in render_template
    template = jinja_env.get_template(value)
  File "/home/airflow/.local/lib/python3.7/site-packages/jinja2/environment.py", line 1010, in get_template
    return self._load_template(name, globals)
  File "/home/airflow/.local/lib/python3.7/site-packages/jinja2/environment.py", line 969, in _load_template
    template = self.loader.load(self, name, self.make_globals(globals))
  File "/home/airflow/.local/lib/python3.7/site-packages/jinja2/loaders.py", line 126, in load
    source, filename, uptodate = self.get_source(environment, name)
  File "/home/airflow/.local/lib/python3.7/site-packages/jinja2/loaders.py", line 218, in get_source
    raise TemplateNotFound(template)
jinja2.exceptions.TemplateNotFound: /opt/airflow/mysql_utils/set_up_database.sql
[2024-05-27T03:02:21.078+0000] {taskinstance.py:1768} ERROR - Task failed with exception
Traceback (most recent call last):
  File "/home/airflow/.local/lib/python3.7/site-packages/airflow/models/taskinstance.py", line 1374, in _run_raw_task
    self._execute_task_with_callbacks(context, test_mode)
  File "/home/airflow/.local/lib/python3.7/site-packages/airflow/models/taskinstance.py", line 1493, in _execute_task_with_callbacks
    task_orig = self.render_templates(context=context)
  File "/home/airflow/.local/lib/python3.7/site-packages/airflow/models/taskinstance.py", line 2115, in render_templates
    original_task.render_template_fields(context)
  File "/home/airflow/.local/lib/python3.7/site-packages/airflow/models/baseoperator.py", line 1179, in render_template_fields
    self._do_render_template_fields(self, self.template_fields, context, jinja_env, set())
  File "/home/airflow/.local/lib/python3.7/site-packages/airflow/utils/session.py", line 75, in wrapper
    return func(*args, session=session, **kwargs)
  File "/home/airflow/.local/lib/python3.7/site-packages/airflow/models/abstractoperator.py", line 606, in _do_render_template_fields
    seen_oids,
  File "/home/airflow/.local/lib/python3.7/site-packages/airflow/models/abstractoperator.py", line 657, in render_template
    template = jinja_env.get_template(value)
  File "/home/airflow/.local/lib/python3.7/site-packages/jinja2/environment.py", line 1010, in get_template
    return self._load_template(name, globals)
  File "/home/airflow/.local/lib/python3.7/site-packages/jinja2/environment.py", line 969, in _load_template
    template = self.loader.load(self, name, self.make_globals(globals))
  File "/home/airflow/.local/lib/python3.7/site-packages/jinja2/loaders.py", line 126, in load
    source, filename, uptodate = self.get_source(environment, name)
  File "/home/airflow/.local/lib/python3.7/site-packages/jinja2/loaders.py", line 218, in get_source
    raise TemplateNotFound(template)
jinja2.exceptions.TemplateNotFound: /opt/airflow/mysql_utils/set_up_database.sql
[2024-05-27T03:02:21.086+0000] {taskinstance.py:1323} INFO - Marking task as FAILED. dag_id=conference_dag, task_id=set_up_database, execution_date=20240527T030220, start_date=20240527T030220, end_date=20240527T030221
[2024-05-27T03:02:21.097+0000] {standard_task_runner.py:105} ERROR - Failed to execute job 85 for task set_up_database (/opt/airflow/mysql_utils/set_up_database.sql; 2750)
[2024-05-27T03:02:21.120+0000] {local_task_job.py:208} INFO - Task exited with return code 1
[2024-05-27T03:02:21.133+0000] {taskinstance.py:2578} INFO - 0 downstream tasks scheduled from follow-on schedule check
